Workbook
Name USD_INR: README!$B$39

Sheet README
A1: Emithran ECAD Engine – Reverse-Engineering Master Data
A2: Electronic-module feature extraction & should-costing reference set. Built 2026-10-20.
A4: Sources
A5: Source file | B5: Content | C5: Used in sheets
A6: DC DC Convertor Final Report (EMUSKI) (3).pdf, 45 pages | B6: Numeros Motors DC-DC converter teardown, BOMs, should-cost, casting/tooling, VAVE, supplier negotiation | C6: DC_Overview … DC_VAVE_Suppliers
A7: BOM-Cost.xlsx (memory folder) | B7: Native Excel behind report pages 28–30 (PCBA & WH BOM cost) | C7: DC_PCBA_BOM, DC_WH_BOM
A8: WH Summary Report.xlsx (memory folder) | B8: Native Excel behind report page 27 (WH should-cost summary) | C8: DC_WH_BOM
A9: PCBA + Harness Drawing - FL285182 + LI15020.zip | B9: OPT Machine Vision LED-light PCBAs: BOM xlsx, PCB requirement docx, 2 PCB drawings, Gerbers, NC drill, pick&place, 2 cable-harness drawings | C9: OPT_* sheets
A11: Sheet index
A12: Sheet | B12: What it holds
A13: DC_Overview | B13: Customer, scope, product spec, physical dims, potting calc, top-level BOM
A14: DC_Teardown | B14: Teardown balloon list and assembly-fitting / joining method
A15: DC_PCBA_BOM | B15: 37-line PCBA BOM: identification (side, family, marking) + cost (MPN, price, discount) with live formulas
A16: DC_PCBA_Features | B16: Formula-driven feature extraction from the PCBA BOM (counts by mount type, side, category, package)
A17: DC_PCBA_Cost | B17: PCBA assembly should-cost (p25) and bare-PCB should-cost (p26)
A18: DC_WH_BOM | B18: Wiring harness components (p14), BOM cost (p28) and should-cost summary (p27)
A19: DC_Body_Casting | B19: ADC12 HPDC body: dims, material, ops 20–70, overheads, runner/tonnage/cycle, alloy, mould cost
A20: DC_Assembly_Cost | B20: Final assembly cost estimate DC-00 (p24) with formulas
A21: DC_Process_Routing | B21: Process routings: PCBA, bare PCB, wire harness, casting
A22: DC_Cost_Scenarios | B22: Costing assumptions, Scenario 1 vs 2, Pareto, cost proposition
A23: DC_VAVE_Suppliers | B23: VAVE ideas, supplier quotes vs should-cost, take-aways
... A30: Data_Issues | B30: Inconsistencies found in the source documents – check before training/validating the engine
A32: Legend
A33: Blue text = hard-coded value transcribed from a source document
A34: Black text = formula / calculated in this workbook
A35: Green text = link to another sheet
A36: Yellow fill = key assumption you can edit (e.g. USD→INR rate)
A38: Global assumptions
A39: USD → INR exchange rate | B39: 86 | C39: INR per USD | D39: Back-solved from source: Total BoM USD 4.0502 → INR 348.32 (BOM-Cost.xlsx); WH 0.10526 USD → 9.0526 INR

Sheet DC_Overview
A1: DC-DC Converter – Project & Product Overview
A2: Source: DC DC Convertor Final Report (EMUSKI) pp. 3–7, 16
A4: Project
A5: Customer | B5: Numeros Motors Pvt Ltd | D5: p3 – EV OEM, commercial 2-wheelers
A6: Analysis by | B6: EMUSKI (Salem, Tamil Nadu) | D6: p1
A7: Scope | B7: Complete teardown, component study, should-costing, VAVE | D7: p3 §2.1
A8: Annual demand | B8: 6000 | C8: units/yr | D8: p3 §2.2
A9: Current sourcing | B9: Domestic supplier, proprietary part (no customer design) | D9: p3
A10: Should-cost date | B10: 15-03-2025 | D10: p25/26
A12: Device specification (market + teardown)
A13: Input voltage | B13: 36 – 72 V DC | D13: p5 §3.4
A14: Output voltage | B14: 12 V ± 0.5 V | D14: p5
A15: Output current | B15: 10 – 15 A | D15: p5
A16: Converter type | B16: DC/DC power converter (synchronous buck, TI LM5116 controller) | D16: p5 + BOM
A17: Wiring | B17: Red: Input, Black: Cathode (GND), Yellow: Output | D17: p5
A18: Overall product weight | B18: 252 | C18: g | D18: p5
A19: Max product width | B19: 52 | C19: mm | D19: p5
A20: Max product length (incl. harness) | B20: 310 | C20: mm | D20: p5
A22: Potting compound consumption
A23: Body inside length | B23: 80 | C23: mm | D23: p7
A24: Body inside width | B24: 54 | C24: mm | D24: p7
A25: Body inside depth | B25: 25 | C25: mm | D25: p7
A26: Fill volume | B26: =B23*B24*B25/1000 -> 108 | C26: ml | D26: report: 108,000 mm³ = 108 ml
A27: Potting density | B27: 1.1 | C27: g/ml
A28: Potting weight | B28: =B26*B27 -> 118.8 | C28: g | D28: report: 118.8 g
A29: Material | B29: Black epoxy encapsulating & potting compound
A31: Top-level BOM (p7)
A32: S.no | B32: Level | C32: Part Number | D32: Description | E32: Material Grade | F32: Commodity | G32: Qty/Assy | H32: UOM
A33: 1 | B33: L0 | C33: DC-00 | D33: DC DC Convertor Assy | E33: - | F33: EM Assy | G33: 1 | H33: EA
A34: 2 | B34: L1 | C34: DC-PCBA-00 | D34: DC Convertor PCBA | E34: - | F34: Electronics | G34: 1 | H34: EA
A35: 3 | B35: L1 | C35: DC-WH-00 | D35: Wiring Harness Assembly | E35: - | F35: Electrical | G35: 1 | H35: EA
A36: 4 | B36: L1 | C36: DC-ME-00 | D36: DC Convertor Body | E36: ADC12 | F36: Casting | G36: 1 | H36: EA
A37: 5 | B37: L1 | C37: DC-C-00 (DC-01 in p24) | D37: Black Epoxy Encapsulating & Potting Compound | E37: - | F37: Chemical | G37: 108 | H37: ml

Sheet DC_Teardown
A1: DC-DC Converter – Teardown & Assembly Fitting
A2: Source: DC DC Convertor Final Report (EMUSKI) p6
A4: Teardown balloons
A5: Balloon | B5: Component | C5: Sub-assembly
A6: 1 | B6: DC Convertor Body | C6: Body
A7: 2 | B7: DC Convertor PCBA | C7: PCBA
A8: 3 | B8: Grommet | C8: WH
A9: 4,5,6 | B9: Yellow, Black & Red wire | C9: WH
A10: 7 | B10: Tubing shrink black | C10: WH
A11: 8 | B11: Wire seal | C11: WH
A12: 9 | B12: Wire terminal | C12: WH
A13: 10 | B13: Connector body | C13: WH
A14: 11 | B14: Connector seal | C14: WH
A15: 12 | B15: Potting compound | C15: Chemical
A17: Assembly fitting details (§4.2)
A18: Balloon No | B18: Component Name | C18: Type of Assembly | D18: Equipment
A19: 2 to 1 | B19: PCBA to Body | C19: Pick & place, Adhesive fit (Resin) | D19: Resin melting & pouring
A20: 3 to 1 | B20: Grommet to Body | C20: Snap fit | D20: Manual
A21: 4,5,6 to 3 | B21: Wire to Grommet | C21: Press fit | D21: Manual
A22: 4,5,6 to 2 | B22: Wire to PCBA | C22: Soldering | D22: Solder
A23: 7 to 4,5,6 | B23: Tube Shrink to Wire | C23: Free fit | D23: Manual
A24: 8 to 4,5,6 | B24: Wire to Wire Seal | C24: Press fit | D24: Manual
A25: 9 to 4,5,6 | B25: Terminal to Wire | C25: Press fit | D25: Crimping
A26: 10 to 9 | B26: Terminal to Connector | C26: Snap fit | D26: Manual
A27: 11 to 10 | B27: Seal to Connector | C27: Free fit | D27: Manual
A28: 12 to 1 | B28: Potting Compound to Body | C28: Adhesive | D28: Manual pouring

Sheet DC_PCBA_BOM
A1: DC-DC Converter PCBA (DC-PCBA-00) – Full BOM with Identification & Cost
A2: Identification cols from report p9 (§4.4.1); cost cols from BOM-Cost.xlsx / report pp29–30. Price per unit at EAU 6000.
A4: Sr | B4: Part Ref | C4: Qty/Assy | D4: Value / Specification | E4: Package / Footprint | F4: MPN | G4: Manufacturer | H4: Part Family (p9) | I4: Marking on component (p9) | J4: Mount (p9) | K4: Mount (cost BOM) | L4: Side (p9) | M4: Side (cost BOM) | N4: Category | O4: Pin count (cost BOM) | P4: Pin (p9) | Q4: Class A/B | R4: Subsystem code | S4: Internal code | T4: Supplier-code column (raw) | U4: EAU | V4: Total Qty/Annum | W4: Volume Unit Price (USD) | X4: Discount % | Y4: Unit Price (USD) | Z4: Extended Price (USD) | AA4: Extended Price (INR) | AB4: Pricing Source | AC4: Pin count (clean)
A5: 1 | B5: DC-PCBA-1 | C5: 1 | D5: HT SCR 600V 20A TO263 AECQ | E5: TO-263-3 | F5: SJ6020N1ATP | G5: Littelfuse Inc. | H5: Transistor | I5: SJ6020N121ND5 | J5: SMD | K5: SMD | L5: Bottom | M5: Top | N5: Active | O5: NA | P5: 3 | Q5: A | S5: PB0006696/001 | T5: SHENGYI S1600 NANYA FR4-86-PY DOOSAN DS-7405S KINGBOARD KB6160C | U5: 6000 | V5: =C5*U5 -> 6000 | W5: 1.89525 | X5: 0.75 | Y5: =W5*(1-X5) -> 0.4738125 | Z5: =Y5*C5 -> 0.4738125 | AA5: =Z5*USD_INR -> 40.747875 | AB5: https://www.digikey.com/en/products/detail/littelfuse-inc/SJ6020N1ATP/11505877?curr=usd&utm_campaign=buynow&utm_medium=aggregator&utm_source=octopart | AC5: 3
A6: 2 | B6: DC-PCBA-2 | C6: 5 | D6: Multilayer Ceramic Capacitors MLCC - SMD/SMT KAM15AR72A223KT NEW GLOBAL PN .022UF 100 A 581-KAM15AR72A223KT | E6: 0603 (1608 metric) | F6: 06031C223K4T2A | G6: KYOCERA AVX | H6: Capacitor-Small | I6: 0.7 x 1.4 mm | J6: SMD | K6: SMD | L6: Bottom | M6: Top | N6: Passive | O6: 2 | P6: 2 | Q6: B | R6: SignalDrive | S6: VC9999860 | T6: X7R tolerance ±20% | U6: 6000 | V6: =C6*U6 -> 30000 | W6: 0.068 | X6: 0.75 | Y6: =W6*(1-X6) -> 0.017 | Z6: =Y6*C6 -> 0.085 | AA6: =Z6*USD_INR -> 7.31 | AB6: https://www.mouser.com/ProductDetail/KYOCERA-AVX/06031C223K4T2A?qs=xhbEVWpZdWeoFw5uxdy8jw%3D%3D | AC6: 2
A7: 3 | B7: DC-PCBA-3 | C7: 1 | D7: WSL-1206 .01 1% EA e3 | E7: 1206 | F7: WSL1206R0100FEA | G7: Vishay | H7: Resistor | I7: R025 | J7: SMD | K7: SMD | L7: Bottom | M7: Top | N7: Passive | O7: 2 | P7: 2 | Q7: B | R7: SignalDrive | S7: VC9999719 | T7: COG tolerance ±5% | U7: 6000 | V7: =C7*U7 -> 6000 | W7: 0.14135 | X7: 0.75 | Y7: =W7*(1-X7) -> 0.0353375 | Z7: =Y7*C7 -> 0.0353375 | AA7: =Z7*USD_INR -> 3.039025 | AB7: https://www.avnet.com/shop/us/products/vishay/wsl1206r0100fea-3074457345625291305?CMP=EMA_Octopart_inventoryfeed_VSE | AC7: 2
A8: 4 | B8: DC-PCBA-4 | C8: 1 | D8: Thick Film Resistors - SMD RLW73P A3 1% R010 600ppm 1k RL | E8: 1225 | F8: RLW73PA3FR010TDF | G8: TE Connectivity / CGS | H8: Resistor | I8: R010 | J8: SMD | K8: SMD | L8: Bottom | M8: Top | N8: Passive | O8: 2 | P8: 2 | Q8: B | R8: Connectors | S8: VC9999582 | T8: X5R tolerance ±20% | U8: 6000 | V8: =C8*U8 -> 6000 | W8: 0.304 | X8: 0.75 | Y8: =W8*(1-X8) -> 0.076 | Z8: =Y8*C8 -> 0.076 | AA8: =Z8*USD_INR -> 6.536 | AB8: https://www.mouser.com/ProductDetail/TE-Connectivity-CGS/RLW73PA3FR010TDF?qs=8Wlm6%252BaMh8R9r5N9GC0%2FKw%3D%3D&srsltid=AfmBOopUfUczM-okoX4Mp45P4v04yg4fRXAPquK4-878ODMXdbe2ny1f | AC8: 2
A9: 5 | B9: DC-PCBA-5 | C9: 5 | D9: 630V 10 000pF C0G 12 06 5% AEC-Q200 | E9: 1206 (3216 mm) | F9: KAM31GCG2J103JU | G9: KYOCERA AVX | H9: Capacitor-Medium | I9: 3.2 x 1.5 x 1.8 mm | J9: SMD | K9: SMD | L9: Bottom | M9: Top | N9: Passive | O9: 2 | P9: 2 | Q9: B | R9: LvDisp | S9: VC9999829 | T9: X7R tolerance ±20% | U9: 6000 | V9: =C9*U9 -> 30000 | W9: 0.191 | X9: 0.75 | Y9: =W9*(1-X9) -> 0.04775 | Z9: =Y9*C9 -> 0.23875 | AA9: =Z9*USD_INR -> 20.5325 | AB9: https://www.mouser.com/ProductDetail/KYOCERA-AVX/KAM31GCG2J103JU?qs=Jm2GQyTW%2Fbgo0D%252B5IFLfEQ%3D%3D | AC9: 2
A10: 6 | B10: DC-PCBA-6 | C10: 2 | D10: IPD60N10 - 75V-100V N-Channel Automotive MOSFET | E10: PG-TO252-3 | F10: IPD60N10S4L12ATMA1 | G10: Infineon | H10: Transistor | I10: 4N10L12 GAL403 | J10: SMD | K10: SMD | L10: Bottom | M10: Top | N10: Active | O10: 2 | P10: 2 | Q10: B | R10: LvDisp | S10: VC9999511 | T10: 2000h D=6.3mm H=8mm Ref. Part number: NICHICON - UCL1V101MCL6GS | U10: 6000 | V10: =C10*U10 -> 12000 | W10: 0.512 | X10: 0.75 | Y10: =W10*(1-X10) -> 0.128 | Z10: =Y10*C10 -> 0.256 | AA10: =Z10*USD_INR -> 22.016 | AB10: https://www.rocelec.com/part/01t4w00000PPBJpAAP-IPD60N10S4L12ATMA1 | AC10: 2
A11: 7 | B11: DC-PCBA-7 | C11: 1 | D11: Thin Film Resistors - SMD 10Kohms .1% 25ppm | E11: 0603 | G11: Vishay | H11: Resistor | I11: 1R00 | J11: SMD | K11: SMD | L11: Bottom | M11: Top | N11: Passive | O11: 2 | P11: 2 | Q11: B | R11: Decoupling | S11: VC9999809 | T11: X5R tolerance ±20% | U11: 6000 | V11: =C11*U11 -> 6000 | W11: 0.14602 | X11: 0.75 | Y11: =W11*(1-X11) -> 0.036505 | Z11: =Y11*C11 -> 0.036505 | AA11: =Z11*USD_INR -> 3.13943 | AB11: https://www.avnet.com/shop/us/products/vishay/tnpw060310k0been-3074457345624830694?CMP=EMA_Octopart_inventoryfeed_VSE | AC11: 2
A12: 8 | B12: DC-PCBA-8 | C12: 2 | D12: Thick Film Resistors 0.25watt 2.2ohms 5% 200ppm | E12: 0603 | F12: RCS06032R20JNEA | G12: Vishay / Dale | H12: Resistor | I12: 2R2 | J12: SMD | K12: SMD | L12: Bottom | M12: Top | N12: Passive | O12: 2 | P12: 2 | Q12: B | R12: TOUCH | S12: VC9999674 | T12: X7R tolerance ±20% | U12: 6000 | V12: =C12*U12 -> 12000 | W12: 0.018 | X12: 0.75 | Y12: =W12*(1-X12) -> 0.0045 | Z12: =Y12*C12 -> 0.009 | AA12: =Z12*USD_INR -> 0.774 | AB12: https://www.mouser.com/ProductDetail/Panasonic/ERJ-PA2J2R2X?qs=IKkN%2F947nfCnLCMYZgM9JQ%3D%3D | AC12: 2
A13: 9 | B13: DC-PCBA-9 | C13: 5 | D13: 50V 1000pF X8 A 581-KAM21BR81H102KM | E13: 0805 (2012 metric) | F13: 08055F102K4T4A | G13: KYOCERA AVX | H13: Capacitor-Very Small | I13: 2 x 1.2 mm | J13: SMD | K13: SMD | L13: Bottom | M13: Top | N13: Passive | O13: 2 | P13: 2 | Q13: B | R13: LoadSwitch | S13: VC9995438 | T13: X5R tolerance ±20% | U13: 6000 | V13: =C13*U13 -> 30000 | W13: 0.037 | X13: 0.75 | Y13: =W13*(1-X13) -> 0.00925 | Z13: =Y13*C13 -> 0.04625 | AA13: =Z13*USD_INR -> 3.9775 | AB13: https://www.mouser.com/ProductDetail/KYOCERA-AVX/08055F102K4T4A?qs=%252BdQmOuGyFcG1iuFvnGB2rg%3D%3D | AC13: 2
A14: 10 | B14: DC-PCBA-10 | C14: 1 | D14: Current Sense Resistors ResMetalStrip 2010 R0 Jumper 1.5W | E14: 2010 | F14: CRF2010-J/-000ELF | G14: Bourns | H14: Resistor | I14: 0 | J14: SMD | K14: SMD | L14: Bottom | M14: Top | N14: Passive | O14: 2 | P14: 2 | Q14: B | R14: LoadSwitch | S14: VC9999470 | T14: Tol. ±20%, Op. Temp. Range (-20 / +105)°C, 1000hrs, D=6.3mm, H=10.0mm MAX | U14: 6000 | V14: =C14*U14 -> 6000 | W14: 0.177 | X14: 0.75 | Y14: =W14*(1-X14) -> 0.04425 | Z14: =Y14*C14 -> 0.04425 | AA14: =Z14*USD_INR -> 3.8055 | AB14: https://www.mouser.com/ProductDetail/Bourns/CRF2010-J-000ELF?qs=sGAEpiMZZMvdGkrng054tx4c7YuULGmGugn2efdB5y0t2nrqxi1I%252Bg%3D%3D | AC14: 2
A15: 11 | B15: DC-PCBA-11 | C15: 1 | D15: 2010 R0 Jumper 1.5W | E15: 2010 | F15: CRF2010-J/-000ELF | G15: Bourns | H15: Resistor | I15: 0 | J15: SMD | K15: SMD | L15: Bottom | M15: Top | N15: Passive | O15: 2 | P15: 2 | Q15: B | R15: TOUCH | S15: VC1010928 | T15: COG tolerance ±5% | U15: 6000 | V15: =C15*U15 -> 6000 | W15: 0.177 | X15: 0.75 | Y15: =W15*(1-X15) -> 0.04425 | Z15: =Y15*C15 -> 0.04425 | AA15: =Z15*USD_INR -> 3.8055 | AB15: https://www.mouser.com/ProductDetail/Bourns/CRF2010-J-000ELF?qs=sGAEpiMZZMvdGkrng054tx4c7YuULGmGugn2efdB5y0t2nrqxi1I%252Bg%3D%3D | AC15: 2
A16: 12 | B16: DC-PCBA-12 | C16: 1 | D16: TVS Diodes 27V 4A 30kV 12pF SOD323 Diode Array | E16: SOD-323-3 | F16: AQ27COM-01FTG | G16: Littelfuse | H16: Diode | I16: 2v | J16: SMD | K16: SMD | L16: Bottom | M16: Top | N16: Active | O16: 2 | P16: 2 | Q16: B | R16: TOUCH | S16: VC9999698 | T16: NP0 tolerance ±5% | U16: 6000 | V16: =C16*U16 -> 6000 | W16: 0.098 | X16: 0.75 | Y16: =W16*(1-X16) -> 0.0245 | Z16: =Y16*C16 -> 0.0245 | AA16: =Z16*USD_INR -> 2.107 | AB16: https://www.mouser.com/ProductDetail/Littelfuse/AQ27COM-01FTG?qs=sGAEpiMZZMvxHShE6Whpu8jG9FO6%252BvaPW4UQ%2FZiLpXs%3D | AC16: 2
A17: 13 | B17: DC-PCBA-13 | C17: 2 | D17: Thick Film Resistors 1watt 470ohms 1% 100ppm | E17: 1218 | F17: CRCW1218470RFKTK | G17: Vishay / Dale | H17: Resistor | I17: 10R0 | J17: SMD | K17: SMD | L17: Bottom | M17: Top | N17: Passive | O17: 2 | P17: 2 | Q17: B | R17: Microcontroller | S17: VC9999667 | T17: X5R tolerance ±20% | U17: 6000 | V17: =C17*U17 -> 12000 | W17: 0.178 | X17: 0.75 | Y17: =W17*(1-X17) -> 0.0445 | Z17: =Y17*C17 -> 0.089 | AA17: =Z17*USD_INR -> 7.654 | AB17: https://www.mouser.com/ProductDetail/Vishay-Dale/CRCW1218470RFKTK?qs=sGAEpiMZZMvdGkrng054t27BJPkTiAfYHce9UbzKfLo%3D | AC17: 2
A18: 14 | B18: DC-PCBA-14 | C18: 2 | D18: 022UF 100 A 581 | E18: 0603 (1608 metric) | F18: 06031C223K4T2A | G18: KYOCERA AVX | H18: Capacitor-Very Small | I18: 0.7 x 1.4 mm | J18: SMD | K18: SMD | L18: Bottom | M18: Top | N18: Passive | O18: 2 | P18: 2 | Q18: B | R18: Microcontroller | S18: VC1011809 | T18: X7R tolerance ±20% | U18: 6000 | V18: =C18*U18 -> 12000 | W18: 0.068 | X18: 0.75 | Y18: =W18*(1-X18) -> 0.017 | Z18: =Y18*C18 -> 0.034 | AA18: =Z18*USD_INR -> 2.924 | AB18: https://www.mouser.com/ProductDetail/KYOCERA-AVX/06031C223K4T2A?qs=xhbEVWpZdWeoFw5uxdy8jw%3D%3D | AC18: 2
A19: 15 | B19: DC-PCBA-15 | C19: 1 | D19: Switching Controllers WIDE RANGE SYNCH BUC K CONTROLLER A 926 | E19: HTSSOP-20 | F19: LM5116MHX/NOPB | G19: Texas Instruments | H19: IC | I19: 3AABC30 LM5116 MH | J19: SMD | K19: SMD | L19: Bottom | M19: Top | N19: Passive | O19: 2 | P19: 20 | Q19: B | R19: TOUCH | S19: VC9999818 | T19: COG tolerance ±5% | U19: 6000 | V19: =C19*U19 -> 6000 | W19: 3.15 | X19: 0.75 | Y19: =W19*(1-X19) -> 0.7875 | Z19: =Y19*C19 -> 0.7875 | AA19: =Z19*USD_INR -> 67.725 | AB19: https://www.mouser.com/ProductDetail/Texas-Instruments/LM5116MHX-NOPB?qs=QbsRYf82W3EaCl%2FW15P7yA%3D%3D | AC19: 20
A20: 16 | B20: DC-PCBA-16 | C20: 1 | D20: 200V 100pF A 581 | E20: 0805(2012) | F20: 08052U101FAT2A | G20: KYOCERA AVX | H20: Capacitor-Big | I20: 2 x 1 mm | J20: SMD | K20: SMD | L20: Bottom | M20: Top | N20: Passive | O20: 2 | P20: 2 | Q20: B | R20: MACS | S20: VC9998432 | U20: 6000 | V20: =C20*U20 -> 6000 | W20: 0.133 | X20: 0.75 | Y20: =W20*(1-X20) -> 0.03325 | Z20: =Y20*C20 -> 0.03325 | AA20: =Z20*USD_INR -> 2.8595 | AB20: https://www.mouser.com/ProductDetail/KYOCERA-AVX/08052U101FAT2A?qs=ZBeOGGPQgEFQ1bbr%252B%2Fh%2FDQ%3D%3D | AC20: 2
A21: 17 | B21: DC-PCBA-17 | C21: 1 | D21: 1m Ohms 1/10 W 0603% 1% AEC-Q200 | E21: 0603 | F21: AR0603FR-071ML | G21: YAGEO | H21: Resistor | I21: 01E | J21: SMD | K21: SMD | L21: Bottom | M21: Top | N21: Passive | O21: 2 | P21: 2 | Q21: B | R21: ExternalInputs | S21: VC9998547 | T21: 1N4148 150mA 75V | U21: 6000 | V21: =C21*U21 -> 6000 | W21: 0.061 | X21: 0.75 | Y21: =W21*(1-X21) -> 0.01525 | Z21: =Y21*C21 -> 0.01525 | AA21: =Z21*USD_INR -> 1.3115 | AB21: https://www.mouser.com/ProductDetail/YAGEO/AR0603FR-071ML?qs=sGAEpiMZZMvdGkrng054t3GzUHVMl1SeG3UrYP8aWJHmY%252B9Ea3hbYQ%3D%3D | AC21: 2
A22: 18 | B22: DC-PCBA-18 | C22: 1 | D22: Resistor de Precisão 750kΩ 1% 1/8W SMD 0805 | E22: 0805 | G22: Outros | H22: Resistor | I22: 7503 | J22: SMD | K22: SMD | L22: Bottom | M22: Top | N22: Passive | O22: 2 | P22: 2 | Q22: B | R22: Decoupling | S22: VC9998428 | U22: 6000 | V22: =C22*U22 -> 6000 | W22: 0.03 | X22: 0.75 | Y22: =W22*(1-X22) -> 0.0075 | Z22: =Y22*C22 -> 0.0075 | AA22: =Z22*USD_INR -> 0.645 | AB22: https://www.ryndackcomponentes.com.br/resistor-de-precis-o-750k-1-1-8w-smd-0805.html | AC22: 2
A23: 19 | B23: DC-PCBA-19 | C23: 1 | D23: Thin Film Resistors - SMD 1/16W 27Kohm 0.5% 25ppm | E23: 0603 | F23: RR0816P-273-D | G23: Susumu | H23: Resistor | I23: 273 | J23: SMD | K23: SMD | L23: Bottom | M23: Top | N23: Passive | O23: 2 | P23: 2 | Q23: B | R23: LvDisp | S23: VC9998608 | T23: Schottky 0.5A 40V | U23: 6000 | V23: =C23*U23 -> 6000 | W23: 0.017 | X23: 0.75 | Y23: =W23*(1-X23) -> 0.00425 | Z23: =Y23*C23 -> 0.00425 | AA23: =Z23*USD_INR -> 0.3655 | AB23: https://www.mouser.in/ProductDetail/Susumu/RR0816P-273-D?qs=nCAm%252BcMdy9zBVcQEyxI7VA%3D%3D | AC23: 2
A24: 20 | B24: DC-PCBA-20 | C24: 1 | D24: Thick Film, AEC-Q200 CRCW Series, 82 ohm, 200 mW, 1%, 50 | E24: 0402 | F24: CRCW040282R0FKEDHP | G24: VISHAY | H24: Resistor | I24: 8202 | J24: SMD | K24: SMD | L24: Bottom | M24: Top | N24: Passive | O24: 2 | P24: 3 | Q24: B | R24: LvDisp | S24: VC9998461 | U24: 6000 | V24: =C24*U24 -> 6000 | W24: 0.026 | X24: 0.75 | Y24: =W24*(1-X24) -> 0.0065 | Z24: =Y24*C24 -> 0.0065 | AA24: =Z24*USD_INR -> 0.559 | AB24: https://www.newark.com/vishay/crcw040282r0fkedhp/surface-mount-chip-resistor-thick/dp/41R4596 | AC24: 2
A25: 21 | B25: DC-PCBA-21 | C25: 1 | D25: Thick Film Resistors 1/4watt 62Kohms 5% | E25: 1206 | F25: CRCW120662K0JNEA | G25: Vishay / Dale | H25: Resistor | I25: 623 | J25: SMD | K25: SMD | L25: Bottom | M25: Top | N25: Passive | O25: 3 | P25: 4 | Q25: B | R25: DAAS | S25: VC9998539 | U25: 6000 | V25: =C25*U25 -> 6000 | W25: 0.009 | X25: 0.75 | Y25: =W25*(1-X25) -> 0.00225 | Z25: =Y25*C25 -> 0.00225 | AA25: =Z25*USD_INR -> 0.1935 | AB25: https://www.mouser.com/ProductDetail/Vishay-Dale/CRCW120662K0JNEA?qs=sGAEpiMZZMvdGkrng054t27YQJ%252BwbTvXlwYrxsvc9PI%3D | AC25: 2
A26: 22 | B26: DC-PCBA-22 | C26: 1 | D26: Thick Film Resistors 1/4watt 9.1Kohms 5% | E26: 1206 | F26: CRCW12069K10JNEA | G26: Vishay / Dale | H26: Resistor | I26: 912 | J26: SMD | K26: SMD | L26: Bottom | M26: Top | N26: Passive | O26: 2 | P26: 5 | Q26: A | R26: LedMux | S26: VC1012556 | T26: LTW-C191DS5 | U26: 6000 | V26: =C26*U26 -> 6000 | W26: 0.009 | X26: 0.75 | Y26: =W26*(1-X26) -> 0.00225 | Z26: =Y26*C26 -> 0.00225 | AA26: =Z26*USD_INR -> 0.1935 | AB26: https://www.mouser.com/ProductDetail/Vishay-Dale/CRCW12069K10JNEA?qs=sGAEpiMZZMvdGkrng054txtDEx%2FRoWGKskbw6g%252Blib4%3D | AC26: 2
A27: 23 | B27: DC-PCBA-23 | C27: 1 | D27: Thick Film Resistors 1206 120Kohms 5% AEC-Q200 | E27: 1206 | F27: ERJ-8GEYJ124V | G27: Panasonic | H27: Resistor | I27: 124 | J27: SMD | K27: SMD | L27: Bottom | M27: Top | N27: Passive | O27: 1 | P27: 6 | Q27: B | R27: Touch | S27: VC1008215 | T27: AM-A10961201 | U27: 6000 | V27: =C27*U27 -> 6000 | W27: 0.014 | X27: 0.75 | Y27: =W27*(1-X27) -> 0.0035 | Z27: =Y27*C27 -> 0.0035 | AA27: =Z27*USD_INR -> 0.301 | AB27: https://www.mouser.com/ProductDetail/Panasonic/ERJ-8GEYJ124V?qs=sGAEpiMZZMvdGkrng054tx7%2F6%252BNA3LAJwwEXY4KYL6w%3D | AC27: 2
A28: 24 | B28: DC-PCBA-24 | C28: 2 | D28: Thick Film Resistors 1/8watt 51Kohms 5% | E28: 0805 | F28: CRCW080551K0JNEA | G28: Vishay / Dale | H28: Resistor | I28: 513 | J28: SMD | K28: SMD | L28: Bottom | M28: Top | N28: Passive | P28: 7 | Q28: A | R28: LedMux | S28: VC1006352 | T28: LTG-1626SM-01 | U28: 6000 | V28: =C28*U28 -> 12000 | W28: 0.005 | X28: 0.75 | Y28: =W28*(1-X28) -> 0.00125 | Z28: =Y28*C28 -> 0.0025 | AA28: =Z28*USD_INR -> 0.215 | AB28: https://www.mouser.com/ProductDetail/Vishay-Dale/CRCW080551K0JNEA?qs=sGAEpiMZZMvdGkrng054tygjBeyq%2FOAOEUdqBiTRmxk%3D | AC28: 2
A29: 25 | B29: DC-PCBA-25 | C29: 1 | D29: Thick Film Resistors 1206 300ohm 5% High VoltageAEC-Q200 | E29: 1206 | F29: KTR18EZPJ301 | G29: ROHM Semiconductor | H29: Resistor | I29: 300 | J29: SMD | K29: SMD | L29: Bottom | M29: Top | N29: Passive | O29: 19 | P29: 8 | Q29: A | R29: LedMux | S29: VC1006352 | T29: LTG-1626SMD-01-T2 | U29: 6000 | V29: =C29*U29 -> 6000 | W29: 0.019 | X29: 0.75 | Y29: =W29*(1-X29) -> 0.00475 | Z29: =Y29*C29 -> 0.00475 | AA29: =Z29*USD_INR -> 0.4085 | AB29: https://www.mouser.com/ProductDetail/ROHM-Semiconductor/KTR18EZPJ301?qs=sGAEpiMZZMvdGkrng054t4QdAY%2FQ0LweIZGcAYPvcrM%3D | AC29: 2
A30: 26 | B30: DC-PCBA-26 | C30: 1 | D30: Thick Film Resistors 1206 120Kohms 5% AEC-Q200 | E30: 1206 | F30: ERJ-8GEYJ124V | G30: Panasonic | H30: Resistor | I30: 125 | J30: SMD | K30: SMD | L30: Bottom | M30: Top | N30: Passive | O30: 2 | P30: 9 | Q30: A | R30: Buzzer | S30: VC9999905 | T30: PKLCS1212E4001-R1 | U30: 6000 | V30: =C30*U30 -> 6000 | W30: 0.014 | X30: 0.75 | Y30: =W30*(1-X30) -> 0.0035 | Z30: =Y30*C30 -> 0.0035 | AA30: =Z30*USD_INR -> 0.301 | AB30: https://www.mouser.com/ProductDetail/Panasonic/ERJ-8GEYJ124V?qs=sGAEpiMZZMvdGkrng054tx7%2F6%252BNA3LAJwwEXY4KYL6w%3D | AC30: 2
A31: 27 | B31: DC-PCBA-27 | C31: 1 | D31: Power Inductors - Leaded 80uH 5A 20% DCR=35.6mOhms | E31: Tray | F31: SHBC12-1R0A0080V | G31: KEMET | H31: Inductor/Choke | I31: Dia-2.8mm | J31: TH | K31: TH | L31: Top | M31: Top | N31: Passive | O31: 3 | P31: 2 | Q31: B | R31: SignalDrive | S31: VC9999947 | T31: Ref component: NXP BC807-25 | U31: 6000 | V31: =C31*U31 -> 6000 | W31: 2.078 | X31: 0.75 | Y31: =W31*(1-X31) -> 0.5195 | Z31: =Y31*C31 -> 0.5195 | AA31: =Z31*USD_INR -> 44.677 | AB31: https://us.rs-online.com/product/kemet/shbc12-1r0a0080v/71823287/?utm_source=octopart&utm_medium=part_sourcing&utm_campaign=partsourcing_octopart_IMP_EX_GR | AC31: 2
A32: 28 | B32: DC-PCBA-28 | C32: 1 | D32: CAP ALUM 330UF 20% 100V RADIAL | E32: Radial, Can | F32: UPS2A331MHD | G32: Nichicon | H32: Capacitor | I32: 330UF 100V | J32: TH | K32: TH | L32: Top | M32: Bot | N32: Passive | O32: 3 | P32: 2 | Q32: A | R32: LedMux | S32: VC9997811 | T32: LP2301BLT1G | U32: 6000 | V32: =C32*U32 -> 6000 | W32: 0.48425 | X32: 0.75 | Y32: =W32*(1-X32) -> 0.1210625 | Z32: =Y32*C32 -> 0.1210625 | AA32: =Z32*USD_INR -> 10.411375 | AB32: https://www.digikey.lv/en/products/detail/nichicon/UPS2A331MHD/2600047 | AC32: 2
A33: 29 | B33: DC-PCBA-29 | C33: 3 | D33: Aluminum Electrolytic Capacitors - SMD | E33: Aluminum Electrolytic Capacitors - SMD | F33: EMLA250ARA331MHA0G | G33: Chemi-Con | H33: Aluminum Electrolytic Capacitor | I33: jH 330 ELA | J33: SMD | K33: SMD | L33: Top | M33: Bot | N33: Passive | O33: 3 | P33: 2 | Q33: B | R33: LedDispDrivers | S33: VC9999954 | T33: Ref. Pn: ON SEMICONDUCTOR BC817-25LT1G | U33: 6000 | V33: =C33*U33 -> 18000 | W33: 0.178 | X33: 0.75 | Y33: =W33*(1-X33) -> 0.0445 | Z33: =Y33*C33 -> 0.1335 | AA33: =Z33*USD_INR -> 11.481 | AB33: https://www.mouser.com/ProductDetail/Chemi-Con/EMLA250ARA331MHA0G?qs=wT7LY0lnAe3000icBfgtBg%3D%3D | AC33: 2
A34: 30 | B34: DC-PCBA-30 | C34: 1 | D34: SMD 16V 470uf 20% AEC-Q200 | E34: Reel | F34: UCQ1C471MCL1GS | G34: Nichicon | H34: Aluminum Electrolytic Capacitor | I34: U0/2 4/OE CD | J34: SMD | K34: SMD | L34: Top | M34: Bot | N34: Passive | O34: 2 | P34: 2 | Q34: B | R34: SignalDrive | S34: VC9997372 | U34: 6000 | V34: =C34*U34 -> 6000 | W34: 0.47 | X34: 0.75 | Y34: =W34*(1-X34) -> 0.1175 | Z34: =Y34*C34 -> 0.1175 | AA34: =Z34*USD_INR -> 10.105 | AB34: https://www.mouser.com/ProductDetail/Nichicon/UCQ1C471MCL1GS?qs=55YtniHzbhBvwO81ezFqGg%3D%3D | AC34: 2
A35: 31 | B35: DC-PCBA-31 | C35: 1 | D35: 2.5 Ohm, 8A, NTC Thermistor | E35: Reel | F35: SCK-2R58 | G35: Voltts | H35: NTC Thermistor | I35: 2.5D-15 mm | J35: TH | K35: TH | L35: Top | M35: Bot | N35: Passive | O35: 2 | P35: 2 | Q35: B | R35: SignalDrive | S35: VC9997159 | U35: 6000 | V35: =C35*U35 -> 6000 | W35: 0.5792 | X35: 0.75 | Y35: =W35*(1-X35) -> 0.1448 | Z35: =Y35*C35 -> 0.1448 | AA35: =Z35*USD_INR -> 12.4528 | AB35: https://www.ebay.com/itm/355742133181?_trkparms=amclksrc%3DITM%26aid%3D1110006%26algo%3DHOMESPLICE.SIM%26ao%3D1%26asc%3D281955%2C282393%2C282314%26meid%3D85182a6b43434cc780d585ca0487fab7%26pid%3D101875%26rk%3D2%26rkt%3D4%26sd%3D395529645706%26itm%3D355742133181%26pmt%3D1%26noa%3D0%26pg%3D2332490%26algv%3DSimVIDwebV3WithCPCExpansionEmbeddingSearchQuerySemanticBroadMatchSingularityRecall%26brand%3DUnbranded&_trksid=p2332490.c101875.m1851&itmprp=cksum%3A35574213318185182a6b43434cc780d585ca0487fab7%7Cenc%3AAQAKAAABQOqalcCsb07ituDYLOrUrH2eG1DBUcAU1siB%252B881ennut1KqikNJ--C2JmJJYbnGBSq9s1cAaLR3u1P2GFHP6cOkMtiQrPwhnArZTi0NFnCkYNs9wPMPnRY0lLYAH0ZUZAibqDPJ%252BbgBETW62dsqLTkadiuzdSV45OfRGieK40izU5dajW0VR3EM8gPgcxvm0tX%252Buzzj%252BII0%252FH1qW1rG4xFo7nXqNmF1u%252BOOcUyZ53oWnYah0Yc6JWdpV0SjCzi64NQseG4%252FPtKndJqVnU7s08uKv2F4apoQtegG4UN00gVF%252BWYwDlmCZrT9c6e0z0p1tnarvCqhwrgPphW%252B%252FsXXsInJCcCFNOlGeWFSdO%252F4KvS0tirl4U6IqbaIio1hqDfl0%252FmZ0%252FPjVU6EaMonOxgB8pDaSTynhTySy39KYOhxEhEg%7Campid%3APL_CLK%7Cclp%3A2332490&itmmeta=01JP9GR4SVCQGP6ZAD5FC4VQEP | AC35: 2
A36: 32 | B36: DC-PCBA-32 | C36: 5 | D36: 630V 10 000pF C0G 12 06 5% AEC-Q200 | E36: 1206 (3216 mm) | F36: KAM31GCG2J103JU | G36: KYOCERA AVX | H36: Capacitor | I36: 3.2 x 1.5 x 1.8 mm | J36: SMD | K36: SMD | L36: Top | M36: Bot | N36: Passive | O36: 2 | P36: 2 | Q36: B | R36: LedMux | S36: VC9997399 | U36: 6000 | V36: =C36*U36 -> 30000 | W36: 0.191 | X36: 0.75 | Y36: =W36*(1-X36) -> 0.04775 | Z36: =Y36*C36 -> 0.23875 | AA36: =Z36*USD_INR -> 20.5325 | AB36: https://www.mouser.com/ProductDetail/KYOCERA-AVX/KAM31GCG2J103JU?qs=Jm2GQyTW%2Fbgo0D%252B5IFLfEQ%3D%3D | AC36: 2
A37: 33 | B37: DC-PCBA-33 | C37: 1 | D37: SMD 1210 1Kohms 1% Tol AEC-Q200 | E37: 1210 (3225) | F37: ERJ-14NF1001U | G37: Panasonic | H37: Resistor | I37: 1001 | J37: SMD | K37: SMD | L37: Top | M37: Bot | N37: Passive | O37: 2 | P37: 2 | Q37: B | R37: LedDispDrivers | S37: VC9996824 | U37: 6000 | V37: =C37*U37 -> 6000 | W37: 0.046 | X37: 0.75 | Y37: =W37*(1-X37) -> 0.0115 | Z37: =Y37*C37 -> 0.0115 | AA37: =Z37*USD_INR -> 0.989 | AB37: https://www.mouser.com/ProductDetail/Panasonic/ERJ-14NF1001U?qs=SsWZTgbPiDCVzC74r8dULw%3D%3D | AC37: 2
A38: 34 | B38: DC-PCBA-34 | C38: 1 | D38: ERJ Series, 1 kohm, ± 5%, 100 mW, 0402 [1005 Metric] | E38: 0402 [1005 Metric] | F38: ERJ-2GEJ102X | G38: PANASONIC | H38: Resistor | I38: 4700 | J38: SMD | K38: SMD | L38: Top | M38: Bot | N38: Passive | O38: 2 | P38: 2 | Q38: B | R38: LedDispDrivers | S38: VC9997254 | U38: 6000 | V38: =C38*U38 -> 6000 | W38: 0.007 | X38: 0.75 | Y38: =W38*(1-X38) -> 0.00175 | Z38: =Y38*C38 -> 0.00175 | AA38: =Z38*USD_INR -> 0.1505 | AB38: https://canada.newark.com/panasonic/erj-2gej102x/res-thick-film-1k-5-0-1w-0402/dp/65T8247 | AC38: 2
A39: 35 | B39: DC-PCBA-35 | C39: 1 | D39: Rectifiers 5 Amp 600 Volts Ultrafast - Low VF | E39: Reel | F39: VS-5ECU06-M3/9AT | G39: Vishay Semiconductors | H39: Diode-Medium | I39: SM 45 | J39: SMD | K39: SMD | L39: Top | M39: Bot | N39: Active | O39: 2 | P39: 2 | Q39: B | R39: SignalDrive | S39: VC9996566 | U39: 6000 | V39: =C39*U39 -> 6000 | W39: 0.33 | X39: 0.75 | Y39: =W39*(1-X39) -> 0.0825 | Z39: =Y39*C39 -> 0.0825 | AA39: =Z39*USD_INR -> 7.095 | AB39: https://www.mouser.com/ProductDetail/Vishay-Semiconductors/VS-5ECU06-M3-9AT?qs=sGAEpiMZZMtbRapU8LlZD86AqDIWVFU%2Fqmw%252BGvu4AfI%3D | AC39: 2
A40: 36 | B40: DC-PCBA-36 | C40: 2 | D40: Zener Diodes | E40: Reel | F40: MMSZ5244C-HE3_A-08 | G40: Vishay | H40: Diode-Small | I40: WE | J40: SMD | K40: SMD | L40: Top | M40: Bot | N40: Active | O40: 2 | P40: 2 | Q40: B | R40: LedDispDrivers | S40: VC9996341 | U40: 6000 | V40: =C40*U40 -> 12000 | W40: 0.057 | X40: 0.75 | Y40: =W40*(1-X40) -> 0.01425 | Z40: =Y40*C40 -> 0.0285 | AA40: =Z40*USD_INR -> 2.451 | AB40: https://www.mouser.com/ProductDetail/Vishay/MMSZ5244C-HE3_A-08?qs=sGAEpiMZZMtbRapU8LlZD8qu4xuMq4%252BSw7PUO5LvpGF2X%252B6jRMr%2FDQ%3D%3D | AC40: 2
A41: 37 | B41: DC-PCBA-37 | C41: 1 | D41: 2L STD PCB, HASL, Silk, 1.6mm thick. | E41: Pcs | F41: SE-59-009-015-00 | G41: India | H41: Bare PCB | I41: 64 x 50 x 1.5 mm | J41: PCB | K41: SMD | L41: Top | M41: Bot | N41: Passive | O41: 2 | Q41: B | R41: LedDispDrivers | S41: VC9996755 | U41: 6000 | V41: =C41*U41 -> 6000 | W41: 0.36935026 | X41: 0.75 | Y41: =W41*(1-X41) -> 0.092337564 | Z41: =Y41*C41 -> 0.092337564 | AA41: =Z41*USD_INR -> 7.9410305 | AB41: As per the calculation | AC41: 0
...

Sheet DC_PCBA_Features
A1: DC-DC PCBA – Extracted Features (formula-driven from DC_PCBA_BOM)
A2: Engine-ready feature vector. All values recalc if the BOM changes. Excludes the bare PCB line where noted.
A4: Feature | B4: Value | C4: Unit | D4: Definition
A5: Unique BOM lines (incl. PCB) | B5: =COUNTA(DC_PCBA_BOM!$B$5:$B$41) -> 37 | C5: lines | D5: Distinct part refs
A6: Unique electronic part lines | B6: =COUNTA(DC_PCBA_BOM!$B$5:$B$41)-COUNTIF(DC_PCBA_BOM!$J$5:$J$41,"PCB") -> 36 | C6: lines | D6: excl. bare PCB
A7: Total placements (component qty) | B7: =SUM(DC_PCBA_BOM!$C$5:$C$41)-SUMIF(DC_PCBA_BOM!$J$5:$J$41,"PCB",DC_PCBA_BOM!$C$5:$C$41) -> 60 | C7: pcs | D7: Σ Qty, excl. PCB
A8: SMD placements | B8: =SUMIF(DC_PCBA_BOM!$J$5:$J$41,"SMD",DC_PCBA_BOM!$C$5:$C$41) -> 57 | C8: pcs | D8: Mount per p9 identification
A9: TH placements | B9: =SUMIF(DC_PCBA_BOM!$J$5:$J$41,"TH",DC_PCBA_BOM!$C$5:$C$41) -> 3 | C9: pcs
A10: SMD share | B10: =B8/B7 -> 0.95
A11: Placements – side Bottom (p9) | B11: =SUMIF(DC_PCBA_BOM!$L$5:$L$41,"Bottom",DC_PCBA_BOM!$C$5:$C$41) -> 43 | C11: pcs | D11: p9 side
A12: Placements – side Top (p9) | B12: =SUMIF(DC_PCBA_BOM!$L$5:$L$41,"Top",DC_PCBA_BOM!$C$5:$C$41)-SUMIF(DC_PCBA_BOM!$J$5:$J$41,"PCB",DC_PCBA_BOM!$C$5:$C$41) -> 17 | C12: pcs | D12: p9 side, excl. PCB
A13: Double-sided SMT required? | B13: =IF(AND(B11>0,COUNTIFS(DC_PCBA_BOM!$L$5:$L$41,"Top",DC_PCBA_BOM!$J$5:$J$41,"SMD")>0),"Yes","No") -> Yes | D13: SMD on both sides → 2 reflow passes
A14: Active placements | B14: =SUMIF(DC_PCBA_BOM!$N$5:$N$41,"Active",DC_PCBA_BOM!$C$5:$C$41) -> 7 | C14: pcs | D14: Category col
A15: Passive placements | B15: =SUMIFS(DC_PCBA_BOM!$C$5:$C$41,DC_PCBA_BOM!$N$5:$N$41,"Passive",DC_PCBA_BOM!$J$5:$J$41,"<>PCB") -> 53 | C15: pcs | D15: excl. bare PCB
A16: Resistor placements | B16: =SUMIF(DC_PCBA_BOM!$H$5:$H$41,"Resistor",DC_PCBA_BOM!$C$5:$C$41) -> 22 | C16: pcs | D16: Part family p9
A17: Capacitor placements | B17: =SUMIF(DC_PCBA_BOM!$H$5:$H$41,"*Capacitor*",DC_PCBA_BOM!$C$5:$C$41) -> 28 | C17: pcs
A18: Semiconductor placements (IC/transistor/diode) | B18: =SUMIF(DC_PCBA_BOM!$H$5:$H$41,"IC",DC_PCBA_BOM!$C$5:$C$41)+SUMIF(DC_PCBA_BOM!$H$5:$H$41,"Transistor",DC_PCBA_BOM!$C$5:$C$41)+SUMIF(DC_PCBA_BOM!$H$5:$H$41,"Diode*",DC_PCBA_BOM!$C$5:$C$41) -> 8 | C18: pcs
A19: Magnetics placements | B19: =SUMIF(DC_PCBA_BOM!$H$5:$H$41,"Inductor*",DC_PCBA_BOM!$C$5:$C$41) -> 1 | C19: pcs
A20: Total solder joints (Σ qty × pin) | B20: =SUMPRODUCT(DC_PCBA_BOM!$C$5:$C$41,DC_PCBA_BOM!$AC$5:$AC$41) -> 139 | C20: joints | D20: Uses cleaned pin col AC (p9 pins; 20–26 reset to 2)
A21: Max pin count single part | B21: =MAX(DC_PCBA_BOM!$AC$5:$AC$41) -> 20 | C21: pins | D21: LM5116 HTSSOP-20
A22: Class A lines | B22: =COUNTIF(DC_PCBA_BOM!$Q$5:$Q$41,"A") -> 6 | C22: lines | D22: High-value / critical
A23: BoM cost (USD) | B23: =DC_PCBA_BOM!Z43 -> 3.8573551 | C23: USD
A24: BoM cost incl. Mtl OH (INR) | B24: =DC_PCBA_BOM!AA45 -> 348.31916 | C24: INR
A25: Top cost line (USD ext.) | B25: =MAX(DC_PCBA_BOM!$Z$5:$Z$41) -> 0.7875 | C25: USD
A26: Top cost line – MPN | B26: =INDEX(DC_PCBA_BOM!$F$5:$F$41,MATCH(B25,DC_PCBA_BOM!$Z$5:$Z$41,0)) -> LM5116MHX/NOPB
A27: Top cost line share of BoM | B27: =B25/B23 -> 0.20415543
A28: Active parts cost share | B28: =SUMIF(DC_PCBA_BOM!$N$5:$N$41,"Active",DC_PCBA_BOM!$Z$5:$Z$41)/B23 -> 0.22432794
A29: TH parts cost share | B29: =SUMIF(DC_PCBA_BOM!$K$5:$K$41,"TH",DC_PCBA_BOM!$Z$5:$Z$41)/B23 -> 0.2036013 | D29: Mount per cost BOM
A30: Average discount applied | B30: =AVERAGE(DC_PCBA_BOM!$X$5:$X$41) -> 0.75 | D30: Volume discount vs. distributor price
A31: Bare PCB size | B31: 64 x 50 x 1.5 mm | C31: mm | D31: p9 marking col (BOM text says 1.6 mm)
A32: Bare PCB layers / finish | B32: 2L, HASL, silkscreen | D32: DC-PCBA-37
A33: Assembly cycle time (total) | B33: =DC_PCBA_Cost!F16 -> 59.44 | C33: s | D33: p25
A35: Package / footprint mix (placements)
A36: Package (normalised) | B36: Lines | C36: Placements | D36: Extended USD
A37: 0402 | B37: =COUNTIF(DC_PCBA_BOM!$E$5:$E$41,"*0402*") -> 2 | C37: =SUMIF(DC_PCBA_BOM!$E$5:$E$41,"*0402*",DC_PCBA_BOM!$C$5:$C$41) -> 2 | D37: =SUMIF(DC_PCBA_BOM!$E$5:$E$41,"*0402*",DC_PCBA_BOM!$Z$5:$Z$41) -> 0.00825
A38: 0603 | B38: =COUNTIF(DC_PCBA_BOM!$E$5:$E$41,"*0603*") -> 6 | C38: =SUMIF(DC_PCBA_BOM!$E$5:$E$41,"*0603*",DC_PCBA_BOM!$C$5:$C$41) -> 12 | D38: =SUMIF(DC_PCBA_BOM!$E$5:$E$41,"*0603*",DC_PCBA_BOM!$Z$5:$Z$41) -> 0.184005
A39: 0805 | B39: =COUNTIF(DC_PCBA_BOM!$E$5:$E$41,"*0805*") -> 4 | C39: =SUMIF(DC_PCBA_BOM!$E$5:$E$41,"*0805*",DC_PCBA_BOM!$C$5:$C$41) -> 9 | D39: =SUMIF(DC_PCBA_BOM!$E$5:$E$41,"*0805*",DC_PCBA_BOM!$Z$5:$Z$41) -> 0.0895
A40: 1206 | B40: =COUNTIF(DC_PCBA_BOM!$E$5:$E$41,"*1206*") -> 8 | C40: =SUMIF(DC_PCBA_BOM!$E$5:$E$41,"*1206*",DC_PCBA_BOM!$C$5:$C$41) -> 16 | D40: =SUMIF(DC_PCBA_BOM!$E$5:$E$41,"*1206*",DC_PCBA_BOM!$Z$5:$Z$41) -> 0.5290875
A41: 1210 | B41: =COUNTIF(DC_PCBA_BOM!$E$5:$E$41,"*1210*") -> 1 | C41: =SUMIF(DC_PCBA_BOM!$E$5:$E$41,"*1210*",DC_PCBA_BOM!$C$5:$C$41) -> 1 | D41: =SUMIF(DC_PCBA_BOM!$E$5:$E$41,"*1210*",DC_PCBA_BOM!$Z$5:$Z$41) -> 0.0115
A42: 1218 | B42: =COUNTIF(DC_PCBA_BOM!$E$5:$E$41,"*1218*") -> 1 | C42: =SUMIF(DC_PCBA_BOM!$E$5:$E$41,"*1218*",DC_PCBA_BOM!$C$5:$C$41) -> 2 | D42: =SUMIF(DC_PCBA_BOM!$E$5:$E$41,"*1218*",DC_PCBA_BOM!$Z$5:$Z$41) -> 0.089
...

Sheet DC_PCBA_Cost
A1: DC-DC PCBA – Assembly & Bare-PCB Should-Cost
A2: Source: DC DC Convertor Final Report (EMUSKI) p25 (PCBA) and p26 (bare PCB). Date 15-03-2025, India, EXW.
A4: PCB assembly should-costing (DC-PCBA-00)
A5: Annual qty | B5: 6000
A6: Batch qty | B6: 500
A7: Batch | B7: Monthly
A8: Part rev | B8: 1
A9: Description | B9: Rate | C9: Cost (INR) | E9: Process | F9: Cycle time (s)
A10: BOM cost | C10: 348.247 | E10: Solder paste process | F10: 5.23
A11: Setup cost | C11: 14.617 | E11: SMD process | F11: 8.06
A12: Process cost | C12: 20.012 | E12: TH process | F12: 8.3
A13: Solder paste material cost | C13: 21.779 | E13: Depaneling | F13: 10.99
A14: Conformal coating material cost | C14: 0 | E14: Testing process | F14: 16.97
A15: Cost of rejection (1% of setup+process+paste) | B15: 0.01 | C15: =B15*SUM(C11:C13) -> 0.56408 | E15: Manual process | F15: 9.89
A16: SG&A (5% of BOM+setup+process+paste) | B16: 0.05 | C16: =B16*SUM(C10:C13) -> 20.23275 | E16: Total product cycle time | F16: =SUM(F10:F15) -> 59.44
A17: Profit (10% of same base) | B17: 0.1 | C17: =B17*SUM(C10:C13) -> 40.4655
A18: ICC (1.5% of BOM) | B18: 0.015 | C18: =B18*C10 -> 5.223705
A19: PCBA Ex-Works cost | C19: =SUM(C10:C18) -> 471.14104 | D19: Source: ₹471.14
A21: Bare PCB should-cost (DC-PCBA-37) – India, annual 6000, batch 500 monthly
A22: Manufacturing cost distribution | B22: Cost (INR) | D22: Process cost breakup | E22: Cost (INR)
A23: Bill of material cost | B23: =B41 -> 18.561 | D23: Inner layer image | E23: 0
A24: Process cost | B24: =E33 -> 9.918 | D24: Lamination | E24: 0
A25: Scrap | B25: 0.854 | D25: Drilling | E25: 5.457
A26: SG&A | B26: 2.278 | D26: Plating | E26: 1.142
A27: Margin + material overhead | B27: 1.233 | D27: Outer layer image | E27: 0.721
A28: ICC | B28: 0.278 | D28: Solder mask | E28: 0.647
A29: TOTAL bare PCB cost | B29: =SUM(B23:B28) -> 33.122 | D29: Silk screen | E29: 0.928
A30: Source total ₹34.785 | D30: Routing | E30: 0.735
D31: Testing | E31: 0.118
D32: Surface finish treatment | E32: 0.17
D33: TOTAL process | E33: =SUM(E23:E32) -> 9.918
A35: Bill of material breakup | B35: Cost (INR)
A36: Core laminate cost | B36: 10.814
A37: Prepreg cost | B37: 0
A38: Copper foil cost | B38: 0
A39: Consumable material cost | B39: 7.51
A40: Surface finish cost | B40: 0.237
A41: TOTAL BOM | B41: =SUM(B36:B40) -> 18.561

Sheet DC_WH_BOM
A1: DC-DC Wiring Harness (DC-WH-00) – Components, BOM Cost & Should-Cost
A2: Sources: report p14 (identification), BOM-Cost.xlsx "Wire Harness_BOM" (p28), WH Summary Report.xlsx (p27)
A4: Component identification (p14 §4.5) – all parts carried "No Marking"
A5: Sr | B5: Part Number | C5: Family | D5: Component spec | E5: Qty/Assy | F5: UOM | G5: Note
A6: 1 | B6: DC-WH-01 | C6: Connector | D6: 3 pin male connector | E6: 1 | F6: EA
A7: 2 | B7: DC-WH-02 | C7: Terminal | D7: AV wire terminal 2.3 mm | E7: 3 | F7: EA
A8: 3 | B8: DC-WH-03 | C8: Seal | D8: Wire seal | E8: 3 | F8: EA
A9: 4 | B9: DC-WH-04 | C9: Wire | D9: Red wire | E9: 20 | F9: cm | G9: Cost BOM lists wire as DC-WH-06..08, 12 AWG GXL, 0.66 m each
A10: 5 | B10: DC-WH-05 | C10: Wire | D10: Black wire | E10: 20 | F10: cm
A11: 6 | B11: DC-WH-06 | C11: Wire | D11: Yellow wire | E11: 20 | F11: cm
A12: 7 | B12: DC-WH-07 | C12: Tube | D12: Tubing shrink BLK | E12: 13 | F12: cm | G12: Cost BOM: DC-WH-04, qty 1 EA
A13: 8 | B13: DC-WH-08 | C13: Rubber | D13: Rubber cable grommet | E13: 1 | F13: EA | G13: Cost BOM: DC-WH-05
A15: Wire harness BOM cost (p28) – EAU 6000
A16: Sl | B16: Part No. | C16: Description | D16: Class | E16: Qty/Assy | F16: Total Qty | G16: Discount % | H16: Cost/pc (USD, net) | I16: Cost/pc (INR) | J16: Amount (INR) | K16: Freight | L16: Duty | M16: Landed (INR) | N16: Reference
A17: 1 | B17: DC-WH-01 | C17: 3 Pin male Connector | D17: HOUS | E17: 1 | F17: =E17*6000 -> 6000 | G17: 0.5 | H17: 0.105263 | I17: =H17*USD_INR -> 9.052618 | J17: =I17*E17 -> 9.052618 | K17: 0 | L17: 0 | M17: =J17+K17+L17 -> 9.052618 | N17: https://prd.sws.co.jp/components/en/detail.php?number_s=61873231
A18: 2 | B18: DC-WH-02 | C18: Av Wire Terminal 2.3 mm | D18: TRML | E18: 3 | F18: =E18*6000 -> 18000 | G18: 0.5 | H18: 0.0121 | I18: =H18*USD_INR -> 1.0406 | J18: =I18*E18 -> 3.1218 | K18: 0 | L18: 0 | M18: =J18+K18+L18 -> 3.1218 | N18: https://prd.sws.co.jp/components/en/detail.php?number_s=15000105
A19: 3 | B19: DC-WH-03 | C19: Wire Seal | D19: SEAL | E19: 3 | F19: =E19*6000 -> 18000 | G19: 0.5 | H19: 0.0103 | I19: =H19*USD_INR -> 0.8858 | J19: =I19*E19 -> 2.6574 | K19: 0 | L19: 0 | M19: =J19+K19+L19 -> 2.6574 | N19: 自動車用部品:Sumitomo Wiring Systems, Ltd
A20: 4 | B20: DC-WH-04 | C20: TUBING SHRINK BLK OD- | D20: TUBE | E20: 1 | F20: =E20*6000 -> 6000 | G20: 0.7 | H20: 0.108222 | I20: =H20*USD_INR -> 9.307092 | J20: =I20*E20 -> 9.307092 | K20: 0 | L20: 0 | M20: =J20+K20+L20 -> 9.307092 | N20: https://www.mouser.com/ProductDetail/Panduit/TV105-.38D20Y?qs=KwArPi4cUoiZh3Qh202YFQ%3D%3D
A21: 5 | B21: DC-WH-05 | C21: Rubber Cable Grommet | D21: GROM | E21: 1 | F21: =E21*6000 -> 6000 | G21: 0.7 | H21: 0.1137 | I21: =H21*USD_INR -> 9.7782 | J21: =I21*E21 -> 9.7782 | K21: 0 | L21: 0 | M21: =J21+K21+L21 -> 9.7782 | N21: https://www.mouser.com/ProductDetail/Essentra/1342664?qs=sGAEpiMZZMsAepjoiJLcxrBr2lVp79XOMDJP%252BK6iKRzPTiq9wiVAhw%3D%3D
A22: 6 | B22: DC-WH-06 | C22: 12 RED | D22: CABL | E22: 0.66 | F22: =E22*6000 -> 3960 | G22: 0.5 | H22: 0.117495 | I22: =H22*USD_INR -> 10.10457 | J22: =I22*E22 -> 6.6690162 | K22: 0 | L22: 0 | M22: =J22+K22+L22 -> 6.6690162 | N22: https://www.awcwire.com/product/gxl-12
A23: 7 | B23: DC-WH-07 | C23: 12 YELLOW | D23: CABL | E23: 0.66 | F23: =E23*6000 -> 3960 | G23: 0.5 | H23: 0.117495 | I23: =H23*USD_INR -> 10.10457 | J23: =I23*E23 -> 6.6690162 | K23: 0 | L23: 0 | M23: =J23+K23+L23 -> 6.6690162 | N23: https://www.awcwire.com/product/gxl-12
A24: 8 | B24: DC-WH-08 | C24: 12 BLACK | D24: CABL | E24: 0.66 | F24: =E24*6000 -> 3960 | G24: 0.5 | H24: 0.117495 | I24: =H24*USD_INR -> 10.10457 | J24: =I24*E24 -> 6.6690162 | K24: 0 | L24: 0 | M24: =J24+K24+L24 -> 6.6690162 | N24: https://www.awcwire.com/product/gxl-12
L25: Total material | M25: =SUM(M17:M24) -> 53.924159
L26: of which wire | M26: =SUMIF(D17:D24,"CABL",M17:M24) -> 20.007049
L27: of which components | M27: =M25-M26 -> 33.91711
A29: Should-costing report – wire harness (p27 / WH Summary Report.xlsx). Annual 6000, batch 500 monthly, India
A30: Costing factor | B30: Rate | C30: INR/unit | D30: Note
A31: Material cost | C31: =M25 -> 53.924159
A32: Process cost | C32: 20.16 | D32: Process detail not given in source
A33: SG&A (5% of BOM+process) | B33: 0.05 | C33: =B33*(C31+C32) -> 3.7042079
A34: Rejection (1% of BOM+process) | B34: 0.01 | C34: =B34*(C31+C32) -> 0.74084159
A35: Packing (1% of BOM+process) | B35: 0.01 | C35: =B35*(C31+C32) -> 0.74084159
A36: ICC (1.5% of material) | B36: 0.015 | C36: =B36*C31 -> 0.80886238
A37: Margin (10% of BOM+process) | B37: 0.1 | C37: =B37*(C31+C32) -> 7.4084159
A38: Ex-Works cost | C38: =SUM(C31:C37) -> 87.487328 | D38: Source: ₹87.49

Sheet DC_Body_Casting
A1: DC Convertor Body (DC-ME-00) – HPDC Should-Cost & Tooling
A2: Source: DC DC Convertor Final Report (EMUSKI) pp16–18, 31–39. ADC12 aluminium, shot-blasted, 1 cavity.
A4: Part & commercial data
A5: Commodity | B5: Casting
A6: Process | B6: High Pressure Die Casting
A7: Annual volume | B7: 6000
A8: Lot size | B8: 500
A9: Part complexity | B9: Low
A10: Supply chain model | B10: Buy
A11: Packaging | B11: Reusable
A12: Incoterms | B12: EX-W
A13: Payment terms | B13: 30 days
A14: Manufacturing / delivery country | B14: India / India
A15: Finish | B15: Shot blasting
A16: Average wall thickness | B16: 2 | C16: mm
A17: Functions | B17: PCBA support/enclosure; heat dissipation via external fins | D17: p17
A19: Material information
A20: Category | B20: Non Ferrous
A21: Family | B21: Aluminum
A22: Grade | B22: ADC 12
A23: Density | B23: 2.74 | C23: g/cc
A24: Material price | B24: 230 | C24: ₹/kg
A25: Scrap price | B25: 92 | C25: ₹/kg
A26: Envelope length | B26: 121 | C26: mm
A27: Envelope width | B27: 57 | C27: mm
A28: Envelope height | B28: 35 | C28: mm
A29: Surface area | B29: 21774 | C29: mm²
A30: Part volume | B30: 28467.15 | C30: mm³
A31: Cavities | B31: 1
A32: Plunger & gating | B32: Cold plunger, tab gating
A33: Finish part weight | B33: 78 | C33: g
A34: Runner & sprue weight | B34: 12 | C34: g
A35: Shot weight | B35: =B33+B34 -> 90 | C35: g
A36: Calc. weight from volume | B36: =B30*B23/1000 -> 77.999991 | C36: g | D36: check vs 78 g measured
A37: Scrap reuse | B37: No
A38: Scrap weight per shot | B38: =B34 -> 12 | C38: g
A39: Scrap recovery % | B39: 0.9
A40: Gross material cost / part | B40: =B35/1000*B24 -> 20.7 | C40: ₹
A41: Scrap recovery / part | B41: =B38/1000*B39*B25 -> 0.9936 | C41: ₹
A42: Net RM cost / part | B42: =B40-B41 -> 19.7064 | C42: ₹ | D42: Source ₹19.71
...

Sheet DC_Assembly_Cost
A1: DC-00 DC-DC Converter – Final Assembly Cost Estimate (Scenario 2)
A2: Source: DC DC Convertor Final Report (EMUSKI) p24. INR, India, annual 6000, lot 500.
A4: Sl | B4: Part Number | C4: Description | D4: Commodity | E4: Qty/Assy | F4: UoM | G4: Part cost/unit (₹) | H4: Total (₹)
A5: 1 | B5: DC-PCBA-00 | C5: DC Convertor PCBA | D5: Electronics | E5: 1 | F5: EA | G5: 505.93 | H5: =E5*G5 -> 505.93
A6: 2 | B6: DC-WH-00 | C6: Wiring Harness Assembly | D6: Electrical | E6: 1 | F6: EA | G6: 87.49 | H6: =E6*G6 -> 87.49
A7: 3 | B7: DC-ME-00 | C7: DC Convertor Body | D7: Casting | E7: 1 | F7: EA | G7: 78.18 | H7: =E7*G7 -> 78.18
A8: 4 | B8: DC-01 | C8: Potting Compound | D8: Chemical | E8: 108 | F8: ml | G8: 0.0559 | H8: =E8*G8 -> 6.0372
G9: Total components | H9: =SUM(H5:H8) -> 677.6372
A11: Operation | B11: Equipment | C11: Qty/Assy | D11: Cycle (s) | E11: Setup (min) | F11: Batch qty | G11: LHR (₹/h) | H11: MHR (₹/h) | I11: Assembly ₹ | J11: Setup ₹ | K11: Total ₹
A12: Body pick & place | B12: Manual | C12: 1 | D12: 10 | E12: 30 | F12: 500 | G12: 149.64 | H12: 0 | I12: =C12*D12/3600*(G12+H12) -> 0.41566667 | J12: =E12/60*(G12+H12)/F12 -> 0.14964 | K12: =I12+J12 -> 0.56530667
A13: PCBA with WH pick & place | B13: Manual | C13: 1 | D13: 15 | E13: 30 | F13: 500 | G13: 149.64 | H13: 0 | I13: =C13*D13/3600*(G13+H13) -> 0.6235 | J13: =E13/60*(G13+H13)/F13 -> 0.14964 | K13: =I13+J13 -> 0.77314
A14: Potting compound mixing | B14: Manual | C14: 1 | D14: 0 | E14: 60 | F14: 500 | G14: 149.64 | H14: 0 | I14: =C14*D14/3600*(G14+H14) -> 0 | J14: =E14/60*(G14+H14)/F14 -> 0.29928 | K14: =I14+J14 -> 0.29928
A15: De-air – vacuum chamber | B15: Vacuum chamber | C15: 1 | D15: 0 | E15: 20 | F15: 500 | G15: 149.64 | H15: 80 | I15: =C15*D15/3600*(G15+H15) -> 0 | J15: =E15/60*(G15+H15)/F15 -> 0.15309333 | K15: =I15+J15 -> 0.15309333
A16: Pour the mixture | B16: Manual | C16: 1 | D16: 5 | E16: 30 | F16: 500 | G16: 149.64 | H16: 0 | I16: =C16*D16/3600*(G16+H16) -> 0.20783333 | J16: =E16/60*(G16+H16)/F16 -> 0.14964 | K16: =I16+J16 -> 0.35747333
A17: Curing | B17: Oven | C17: 1 | D17: 60 | E17: 30 | F17: 500 | G17: 149.64 | H17: 120 | I17: =C17*D17/3600*(G17+H17) -> 4.494 | J17: =E17/60*(G17+H17)/F17 -> 0.26964 | K17: =I17+J17 -> 4.76364
A18: Inspection | B18: Manual | C18: 1 | D18: 10 | E18: 0 | F18: 500 | G18: 149.64 | H18: 120 | I18: =C18*D18/3600*(G18+H18) -> 0.749 | J18: =E18/60*(G18+H18)/F18 -> 0 | K18: =I18+J18 -> 0.749
J19: Total process | K19: =SUM(K12:K18) -> 7.6609333
A20: Note: assembly/setup ₹ rebuilt as cycle×(LHR+MHR) and setup×LHR/batch – reproduces source ₹7.66 within rounding.
A22: Summary
A23: Components cost | C23: =H9 -> 677.6372
A24: Assembly cost | C24: =K19 -> 7.6609333
A25: Assembly scrap | B25: 0.0025 | C25: =B25*(C23+C24) -> 1.7132453
A26: Assembly OH | B26: 0.1 | C26: =B26*C24 -> 0.76609333
A27: Final manufactured cost | C27: =SUM(C23:C26) -> 687.77747
A28: Packaging | B28: 0.0025 | C28: =B28*C27 -> 1.7194437
A29: FINAL EX-WORKS COST | C29: =C27+C28 -> 689.49692 | D29: Source ₹689.49
A31: Tooling: DC-ME-00 body die | C31: 510672 | D31: ₹ one-time

Sheet DC_Process_Routing
A1: DC-DC Converter – Manufacturing Process Routings (DFM)
A2: Source: DC DC Convertor Final Report (EMUSKI) pp10–13, 15–16, 18
A4: PCBA (pp10–12)
A5: OP No | B5: Process | C5: Spec | D5: Equipment | E5: Control / remarks
A6: 10 | B6: Child parts inward inspection | C6: As per QAP | D6: - | E6: Data sheet verification & visual inspection
A7: 20 | B7: In loader | C7: As per WI | D7: SMT assy line | E7: Top side
A8: 30 | B8: Laser marking | C8: As per WI | D8: SMT assy line | E8: Top side
A9: 40 | B9: Bar code reader | C9: As per WI | D9: SMT assy line | E9: Top side
A10: 50 | B10: Solder paste printing | C10: As per WI | D10: SMT assy line | E10: Top side
A11: 60 | B11: Solder paste inspection | C11: As per WI | D11: SMT assy line | E11: Top side
A12: 70 | B12: Pick and place | C12: As per WI | D12: SMT assy line | E12: Top side
A13: 80 | B13: Reflow soldering | C13: As per WI | D13: SMT assy line | E13: Top side
A14: 90 | B14: AOI | C14: As per WI | D14: SMT assy line | E14: Top side
A15: 100 | B15: Unloader | C15: As per WI | D15: SMT assy line | E15: Top side
A16: 110 | B16: Conveyor
A17: 120 | B17: In loader – bottom side | C17: As per WI | D17: SMT assy line | E17: Bottom side
A18: 130 | B18: Solder paste printing | C18: As per WI | D18: SMT assy line | E18: Bottom side
A19: 140 | B19: Solder paste inspection | C19: As per WI | D19: SMT assy line | E19: Bottom side
A20: 150 | B20: Pick and place | C20: As per WI | D20: SMT assy line | E20: Bottom side
A21: 160 | B21: Reflow soldering | C21: As per WI | D21: SMT assy line | E21: Bottom side
A22: 170 | B22: AOI | C22: As per WI | D22: SMT assy line | E22: Bottom side
A23: 180 | B23: Unloader | C23: As per WI | D23: SMT assy line | E23: Bottom side
A24: 190 | B24: Conveyor | C24: As per WI
A25: 200 | B25: Washing | C25: As per WI
A26: 210 | B26: Axial component semi-preforming | C26: As per WI | D26: Off-line process | E26: For THT line
A27: 220 | B27: Selective wave soldering | C27: As per WI | D27: Off-line process | E27: For THT line
A28: 230 | B28: Hand soldering | C28: As per WI | E28: For WH assembly
A29: 240 | B29: Washing | C29: As per WI | E29: Cleaning op
A30: 250 | B30: ICT | C30: As per WI | E30: Circuit test
A31: 260 | B31: Depanel (tab routing) | C31: As per WI
A32: 280 | B32: Final inspection | C32: As per QAP | D32: Testing equipment | E32: Visual
A33: 290 | B33: Packing & warehousing | C33: As per IC | D33: Returnable packing
A34: 300 | B34: Delivery | C34: As per Incoterms | D34: Road
A36: Bare PCB (pp12–13)
A37: OP No | B37: Process | C37: Spec | D37: Equipment | E37: Control / remarks
A38: 10 | B38: Child parts inward inspection | C38: As per QAP | D38: - | E38: Data sheet verification & in-house inspection
A39: 20 | B39: Inner layer image | C39: As per WI | D39: Exposing machine
A40: 30 | B40: Lamination | C40: As per WI | D40: Pressing machine
A41: 40 | B41: Drilling | C41: As per WI | D41: Drilling machine
A42: 50 | B42: Plating | C42: As per WI | D42: Plating bath
...

Sheet DC_Cost_Scenarios
A1: DC-DC Converter – Costing Assumptions & Scenarios
A2: Source: DC DC Convertor Final Report (EMUSKI) pp19–22
A4: Should-costing considerations (§5.1)
A5: Attribute | B5: Mechanical commodities | C5: EE & EC commodities
A6: Should-costing location | B6: India | C6: India
A7: No. of shifts | B7: Three | C7: Three
A8: Batch volume | B8: 500 Nos | C8: 500 Nos
A9: Tooling cost estimation | B9: Required | C9: NA
A10: Incoterms | B10: Ex Works | C10: Ex Works
A11: OH | B11: 13% on process cost | C11: 5% on total cost
A12: Margin | B12: 10% on total cost | C12: 10% on total cost
A13: ICC | B13: 1.5% on RM cost | C13: 1.5% on RM cost
A14: Rejection | B14: 1% on overall cost | C14: 1% on overall cost
A15: RM rate reference | B15: SIAM report | C15: Online website
A16: Scrap recovery rate | B16: 40% | C16: 40%
A17: Standard parts | B17: Bought-out | C17: Bought-out
A19: Overall cost breakdown (₹/unit)
A20: Element | B20: Scenario 1 | C20: Scenario 2 | D20: Δ ₹ | E20: Δ %
A21: Assumption – component procurement batch | B21: 1000 Nos | C21: 5000 Nos
A22: Assumption – PCBA & WH assembly batch | B22: 500 Nos | C22: 500 Nos
A23: PCBA | B23: 615.51 | C23: 505.93 | D23: =C23-B23 -> -109.58 | E23: =IF(B23=0,0,D23/B23) -> -0.17803123
A24: WH | B24: 107.88 | C24: 87.49 | D24: =C24-B24 -> -20.39 | E24: =IF(B24=0,0,D24/B24) -> -0.1890063
A25: Body | B25: 78.18 | C25: 78.18 | D25: =C25-B25 -> 0 | E25: =IF(B25=0,0,D25/B25) -> 0
A26: Other cost | B26: 11.15 | C26: 4.2 | D26: =C26-B26 -> -6.95 | E26: =IF(B26=0,0,D26/B26) -> -0.62331839
A27: Potting | B27: 10.06 | C27: 6.04 | D27: =C27-B27 -> -4.02 | E27: =IF(B27=0,0,D27/B27) -> -0.39960239
A28: Assembly cost | B28: 8.71 | C28: 7.66 | D28: =C28-B28 -> -1.05 | E28: =IF(B28=0,0,D28/B28) -> -0.12055109
A29: TOTAL | B29: =SUM(B23:B28) -> 831.49 | C29: =SUM(C23:C28) -> 689.5 | D29: =SUM(D23:D28) -> -141.99 | E29: =D29/B29 -> -0.17076573
A30: Source totals: S1 ₹831.49, S2 ₹689.49
A32: Pareto – Scenario 2
A33: Element | B33: ₹ | C33: Share | D33: Cumulative
A34: PCBA | B34: =C23 -> 505.93 | C34: =B34/C$29 -> 0.7337636 | D34: =SUM($C$34:C34) -> 0.7337636
A35: WH | B35: =C24 -> 87.49 | C35: =B35/C$29 -> 0.12688905 | D35: =SUM($C$34:C35) -> 0.86065265
A36: Body | B36: =C25 -> 78.18 | C36: =B36/C$29 -> 0.11338651 | D36: =SUM($C$34:C36) -> 0.97403916
A37: Assembly cost | B37: =C28 -> 7.66 | C37: =B37/C$29 -> 0.0111095 | D37: =SUM($C$34:C37) -> 0.98514866
A38: Potting | B38: =C27 -> 6.04 | C38: =B38/C$29 -> 0.008759971 | D38: =SUM($C$34:C38) -> 0.99390863
A39: Other cost | B39: =C26 -> 4.2 | C39: =B39/C$29 -> 0.0060913706 | D39: =SUM($C$34:C39) -> 1
A40: Report: PCBA ≈73% of total; top-3 drivers PCBA, Body, WH
A42: Cost proposition by sub-assembly – Scenario 2 (₹)
A43: Sub-assembly | B43: Material | C43: Process | D43: Other | E43: Total | F43: Material %
A44: PCBA | B44: 366.81 | C44: 66.33 | D44: 72.79 | E44: =SUM(B44:D44) -> 505.93 | F44: =B44/E44 -> 0.72502125
...

Sheet DC_VAVE_Suppliers
A1: DC-DC Converter – VAVE Ideas, Supplier Negotiation & Take-aways
A2: Source: DC DC Convertor Final Report (EMUSKI) pp40–45. YTC = yet to confirm.
A4: VAVE idea generation (method V = P→/C↓)
A5: S.no | B5: Idea | C5: Affected part | D5: Current cost ₹ | E5: Expected cost | F5: Validation | G5: Type of change
A6: 1 | B6: Surface finish change HASL → OSP | C6: DC-PCBA-37 bare PCB | D6: 0.212 | F6: YTC | G6: Process
A7: 2 | B7: Remove the 3 slots in PCB profile, make it rectangular | C7: DC-PCBA-37 bare PCB | D7: 9.67 | F7: YTC | G7: Design
A8: 3 | B8: Soldering → press-fit / avoid THT components | C8: DC-PCBA-2, -27, -31 | D8: 8.3 | F8: YTC | G8: Design
A9: 4 | B9: WH soldering → connector assembly | C9: DC-PCBA-00 | F9: YTC | G9: Design
A10: 5 | B10: Local supplier for ICs | C10: DC-PCBA-15 | D10: 89 | F10: YTC | G10: Supplier
A11: 6 | B11: 2nd source for class-A components | F11: YTC | G11: Supplier
A12: 7 | B12: Body material Al → plastic | C12: DC-ME-00 | D12: 85.47 | F12: YTC | G12: Material
A13: 8 | B13: Process change to Al extrusion | C13: DC-ME-00 | D13: 85.47 | F13: YTC | G13: Process
A14: 9 | B14: Process change to sheet metal | C14: DC-ME-00 | D14: 85.47 | F14: YTC | G14: Process
A15: 10 | B15: Casting supplier change to Coimbatore | C15: DC-ME-00 | D15: 85.47 | F15: YTC | G15: Supplier
A16: 11 | B16: PCBA assembly supplier → local supplier | C16: DC-PCBA-00 | D16: 601.52 | F16: YTC | G16: Supplier
A17: 12 | B17: Wire-harness supplier → local supplier | C17: DC-WH-00 | D17: 118.5 | F17: YTC | G17: Supplier
A18: 13 | B18: Replace potting compound with screws | C18: DC-C-011 | D18: 10.06 | F18: YTC | G18: Design
A20: Market: complete DC-DC converter suppliers (tentative selling price ₹)
A21: Manufacturer | B21: Tentative price ₹ | C21: vs should-cost
A22: Ucal Fuel Systems Ltd. | B22: 1050 | C22: =B22/DC_Assembly_Cost!C29-1 -> 0.52284945
A23: Mind Corporation Ltd | B23: 1500 | C23: =B23/DC_Assembly_Cost!C29-1 -> 1.1754992
A24: Foxconn India Pvt Ltd | B24: 780 | C24: =B24/DC_Assembly_Cost!C29-1 -> 0.13125959
A26: Supplier negotiations
A27: Part | B27: Supplier | C27: Location | D27: Scope | E27: Initial quote ₹ | F27: Negotiated ₹ | G27: Reduction | H27: Should-cost ₹ | I27: Negotiation lever
A28: DC-ME-00 body | B28: Enkey Engineering Works | C28: Coimbatore | D28: RM, HPDC, shot blasting, inspection, packing; EXW; dev cost extra | E28: 115 | F28: 70 | G28: =1-F28/E28 -> 0.39130435 | H28: 78.18 | I28: Supplier assumed higher input weight & tonnage; should-cost shows 150 t and 90 g shot sufficient
A29: DC-PCBA-00 (+final assy, excl. WH & body) | B29: OMGVH Electronics Pvt Ltd | C29: Bangalore | D29: Bare PCB, component procurement, PCBA, inspection, test, final assy | E29: 1450 | F29: 1050 | G29: =1-F29/E29 -> 0.27586207 | H29: 524 | I29: Batch 500 → consolidated multi-customer component buys; alternative components
A30: DC-WH-00 harness | B30: WH Technology Pvt Ltd (S1) / AAYS Solutions Pvt Ltd (S2) | C30: Bangalore | D30: Component procurement, assembly, inspection, test, packing | E30: 98 | F30: 76.53 | G30: =1-F30/E30 -> 0.21908163 | H30: 87.49 | I30: Second-source quote
A32: Supplier quote total vs should-cost total | E32: 1197 | H32: 689
A34: Take-aways (p45)
A35: Major cost driver: electronic components (ICs, capacitors, resistors); pricing depends on purchase volume.
A36: Wiring harness & casting: better pricing from local suppliers.
A37: Local PCBA makers cannot match OEM component pricing – OEMs consolidate demand across products.
A38: Sourcing from China worth exploring; transport + duty add ~20–25%.
A39: For moderate-volume, complex PCBA (>6 layers) China is more cost-effective; duties lower on complex parts.
A41: Part | B41: Description | C41: Suggestion
A42: DC-PCBA-00 | B42: DC Convertor PCBA | C42: Source from a supplier buying components in higher volume, or order all 6000 as one batch; implement VAVE
A43: DC-WH-00 | B43: Wiring harness assembly | C43: Source from local supplier
A44: DC-ME-00 | B44: DC Convertor body | C44: Source from local supplier (Coimbatore)
A45: DC-C-00 | B45: Potting compound | C45: Add scope to PCBA supplier
A46: DC-00 | B46: DC-DC Convertor Assy | C46: Local manufacturer with higher batch qty

Sheet OPT_PCBA_BOM
A1: OPT LED-Light PCBAs – BOM (LI15020-W, FL285182-W)
A2: Source: PCBA BOM (FL285182 + LI15020).xlsx inside the drawing zip
A4: Light Model | B4: Component Type | C4: OPT Item Code | D4: Component Specification | E4: Supplier MPN / PCB Reference | F4: Manufacturer | G4: LED Color | H4: Unit | I4: Quantity per PCBA Set
A5: LI15020-W | B5: PCB | C5: 24030011063 | D5: Custom PCB, 2 Layers, 2-up Panel, FR-4, 139.8 x 55.6 x 1.6 mm | E5: OPT-LI15020-X7-V2.3.2 | F5: Custom PCB (Gerber Supplied) | H5: PCS | I5: 1
A6: LI15020-W | B6: LED | C6: 20010000135 | D6: 3mm Through-Hole LED, White, CCT 5800-6800K, Vf 2.75-2.85V at IF 20mA, luminous intensity 7500-9500mcd, lead length 23±2mm, lead width 0.55±0.1mm | E6: 304WC4P-W5-3PF | F6: Shenzhen Chengchuangxi Optoelectronics Co., Ltd. | G6: White | H6: PCS | I6: 84
A7: LI15020-W | B7: Resistor | C7: 23020000280 | D7: SMD Resistor, 1206, 390 Ohm, 1/4W, 1% | E7: RC1206FR-07390RL | F7: YAGEO | H7: PCS | I7: 12
A8: LI15020-W | B8: Cable Harness | C8: 21010000921 | D8: 2-core 24AWG robot cable, 2PIN male connector, L=800mm, with cable stop, sheath φ4.1 black, drag-chain compatible | E8: GYX0.8M-2P-R-Y-V1.0N | H8: PCS | I8: 1
A9: FL285182-W | B9: PCB | C9: 24030000651 | D9: Custom PCB, FR-4, 273.7 x 170.7 x 1.0 mm | E9: OPT-FL285182-X6-V1.0.2 | F9: Custom PCB (Gerber Supplied) | H9: PCS | I9: 1
A10: FL285182-W | B10: LED | C10: 20020000021 | D10: 3528 SMD LED, White, CCT 5000-7000K, Vf 3.5V, IF 20mA | E10: S3528W8D05-1CY3 | F10: Shenzhen Chengchuangxi Optoelectronics Co., Ltd. | G10: White | H10: PCS | I10: 534
A11: FL285182-W | B11: Resistor | C11: 23020000268 | D11: SMD Thick Film Resistor, 0805, 200 Ohm, 1/8W, 150V, 1% | E11: RC0805FR-07200RL | F11: YAGEO | H11: PCS | I11: 89
A12: FL285182-W | B12: Cable Harness | C12: 21010000941 | D12: 2-core 24AWG robot cable, 2PIN male connector, L=900mm, no cable stop, sheath φ4.1 black, drag-chain compatible | E12: GYX0.9M-2P-R-N-V1.0N | H12: PCS | I12: 1
A13: FL285182-W | B13: Heat Shrink Tube | C13: 28010000067 | D13: Heat shrink tube, φ5, RSFR-H, PE, 200m/roll | E13: RSFR-H | H13: PCS | I13: 0.01
A15: Summary table (from same file)
A16: Light Model | B16: PCB Reference | C16: LED MPN | D16: LED Manufacturer | E16: LED Quantity per PCBA Set | F16: Resistor MPN(s) | G16: Resistor Quantity per PCBA Set
A17: LI15020-W | B17: OPT-LI15020-X7-V2.3.2 | C17: 304WC4P-W5-3PF | D17: Shenzhen Chengchuangxi Optoelectronics Co., Ltd. | E17: 84 | F17: RC1206FR-07390RL (12) | G17: 12
